<?xml version="1.0" ?>
<robot name="myrobot" xmlns:xacro="http://www.ros.org/wiki/xacro">
<xacro:include filename="$(find m2wr_description)/urdf/materials.xacro" />
<xacro:include filename="$(find self_balancing_robot)/urdf/denge.gazebo" />

<!-- şase  -->
  <link name="link_chassis">
    <!-- pose and inertial -->
    <pose>0 0 0.1 0 0 0</pose>
    <inertial>
      <mass value="0.5"/>
      <origin rpy="0 0 0" xyz="0 0 0"/>
      <inertia ixx="0.00030170833" ixy="0" ixz="0" iyy="0.00165104166" iyz="0" izz="0.00135066666"/>
    </inertial>
    <!-- body -->
    <collision name="collision_chassis">
    <origin xyz="0 0 0" rpy="0 0 0"/>
      <geometry>
        <box size="0.085 0.18 0.004"/>
      </geometry>
    </collision>
    <visual>
      <origin rpy="0 0 0" xyz="0 0 0"/>
      <geometry>
        <box size="0.085 0.18 0.004"/>
      </geometry>
      <material name="yellow"/>
    </visual>
</link>

<link name="link_chassis_2">
  <inertial>
    <mass value = "0.5"/>
    <origin xyz="0 0 0" rpy="0 0 0"/>
    <inertia ixx="0.00030170833" ixy="0" ixz="0" iyy="0.00165104166" iyz="0" izz="0.00135066666"/>
    </inertial>
    <visual>
        <origin xyz="0 0 0" rpy="0 0 0" />
        <geometry>
        <box size="0.085 0.18 0.004"/>
        </geometry>
        <material name="yellow" />
    </visual>
    <collision>
        <origin xyz="0 0 0" rpy="0 0 0"/>
        <geometry>
        <box size="0.085 0.18 0.004"/>
        </geometry>
    </collision>
    </link>
      <joint name="joint_chassis_2" type="fixed">
      <origin xyz="0 0 0.225" rpy="0 0 0"/>
      <parent link="link_chassis"/>
      <child link="link_chassis_2"/>
  </joint>

  <link name="link_chassis_3">
  <inertial>
    <mass value = "0.5"/>
    <origin xyz="0 0 0" rpy="0 0 0"/>
    <inertia ixx="0.00030170833" ixy="0" ixz="0" iyy="0.00165104166" iyz="0" izz="0.00135066666"/>
    </inertial>
    <visual>
        <origin xyz="0 0 0" rpy="0 0 0" />
        <geometry>
        <box size="0.085 0.18 0.004"/>
        </geometry>
        <material name="yellow" />
    </visual>
    <collision>
        <origin xyz="0 0 0" rpy="0 0 0"/>
        <geometry>
        <box size="0.085 0.18 0.004"/>
        </geometry>
    </collision>
    </link>
      <joint name="joint_chassis_3" type="fixed">
      <origin xyz="0 0 0.115" rpy="0 0 0"/>
      <parent link="link_chassis"/>
      <child link="link_chassis_3"/>
  </joint>



<!--motorlar-->>



<link name="tekerlek_motor_sag">
  <inertial>
    <mass value = "0.2"/>
    <origin xyz="0 0 0" rpy="0 0 0"/>
    <inertia ixx="0.0001" ixy="0" ixz="0" iyy="0.00013" iyz="0" izz="4.541666666666668e-05" />
    </inertial>
    <visual>
        <origin xyz="0 0 0" rpy="0 0 0" />
        <geometry>
        <box size="0.08 0.04 0.05"/>
        </geometry>
        <material name="black" />
    </visual>
    <collision>
        <origin xyz="0 0 0" rpy="0 0 0"/>
        <geometry>
        <box size="0.08 0.04 0.05"/>
        </geometry>
    </collision>
    </link>
      <joint name="joint_motor_sag" type="fixed">
      <origin xyz="0 0.09 -0.02" rpy="0 0 0"/>
      <parent link="link_chassis"/>
      <child link="tekerlek_motor_sag"/>
  </joint>


<link name="tekerlek_motor_sol">
   <inertial>
    <mass value = "0.2"/>
    <origin xyz="0 0 0" rpy="0 0 0"/>
    <inertia ixx="0.0001" ixy="0" ixz="0" iyy="0.00013" iyz="0" izz="4.541666666666668e-5" />
    </inertial>
    <visual>
        <origin xyz="0 0 0" rpy="0 0 0" />
        <geometry>
        <box size="0.08 0.04 0.05"/>
        </geometry>
        <material name="black" />
    </visual>
    <collision>
        <origin xyz="0 0 0" rpy="0 0 0"/>
        <geometry>
       <box size="0.08 0.04 0.05"/>
        </geometry>
    </collision>
    </link>
      <joint name="joint_motor_sol" type="fixed">
       <origin xyz="0 -0.09 -0.02" rpy="0 0 0"/>
      <parent link="link_chassis"/>
      <child link="tekerlek_motor_sol"/>
 </joint>



<!--*******************************************************************************-->
<!--teker ile motor arasındaki cubuklar -->
<!--SAG CUBUK-->
<link name="teker_cubuk_sag">
    <inertial>
      <mass value="0.05" />
      <origin xyz="0 0 0" rpy="1.570796327 0 0"/>
      <inertia ixx="6.6666666666666675e-6" ixy="0" ixz="0" iyy="0" iyz="0" izz="6.6666666666666675e-06" />
    </inertial>
        <visual>
        <origin xyz="0 0 0" rpy="1.570796327 0 0"/>
        <geometry>
        <cylinder radius="0.005" length="0.02"/>
        </geometry>
        <material name="white" />
    </visual>

    <collision>
        <origin xyz="0 0 0" rpy="1.570796327 0 0"/>
        <geometry>
        <cylinder radius="0.005" length="0.02"/>
        </geometry>
    </collision>
    </link>

    <joint name="joint_cubuk_sag" type="fixed">
    <origin xyz="0 0.03 0" rpy=" 0 0 0"/>
    <parent link="tekerlek_motor_sag"/>
    <child link="teker_cubuk_sag"/>
  </joint>
 <!--SOL CUBUK-->
   <link name="teker_cubuk_sol">
    <inertial>
      <mass value="0.05" />
      <origin xyz="0 0 0" rpy="1.570796327 0 0"/>
      <inertia ixx="6.6666666666666675e-06" ixy="0" ixz="0" iyy="0" iyz="0" izz="6.6666666666666675e-06" />
    </inertial>
        <visual>
        <origin xyz="0 0 0" rpy="1.570796327 0 0"/>
        <geometry>
        <cylinder radius="0.005" length="0.02"/>
        </geometry>
        <material name="gray" />
    </visual>

    <collision>
        <origin xyz="0 0 0" rpy="1.570796327 0 0"/>
        <geometry>
        <cylinder radius="0.005" length="0.02"/>
        </geometry>
    </collision>
    </link>

    <joint name="joint_cubuk_sol" type="fixed">
    <origin xyz="0 -0.03 0" rpy=" 0 0 0"/>
    <parent link="tekerlek_motor_sol"/>
    <child link="teker_cubuk_sol"/>
</joint>      


  <!--sağ tekerlek--> 

<link name="link_right_wheel">
    <inertial>
      <mass value="1"/>
      <origin rpy="0 1.5707 1.5707" xyz="0 0 0"/>
      <inertia ixx="0.0006" ixy="0" ixz="0" iyy="0.0006" iyz="0" izz="0.00125"/>
    </inertial>
    <collision name="link_right_wheel_collision">
      <origin rpy="0 1.5707 1.5707" xyz="0 0 0"/>
      <geometry>
        <cylinder length="0.008" radius="0.05"/>
      </geometry>
    </collision>
    <visual name="link_right_wheel_visual">
      <origin rpy="0 1.5707 1.5707" xyz="0 0 0"/>
      <geometry>
        <cylinder length="0.008" radius="0.05"/>
      </geometry>
    </visual>
  </link>
  
  <joint name="joint_right_wheel" type="continuous">
    <origin rpy="0 0 0" xyz="0 0 0"/>
    <child link="link_right_wheel"/>
    <parent link="teker_cubuk_sag"/>
    <axis rpy="0 0 0" xyz="0 1 0"/>
    <limit effort="10000" velocity="1000"/>
    <joint_properties damping="1.0" friction="1.0"/>
</joint>

<!--sol tekerlek --> 

<link name="link_left_wheel">
    <inertial>
      <mass value="1"/>
      <origin rpy="0 1.5707 1.5707" xyz="0 0 0"/>
      <inertia ixx="0.0006" ixy="0" ixz="0" iyy="0.0006" iyz="0" izz="0.00125"/>
    </inertial>
    <collision name="link_left_wheel_collision">
     <origin rpy="0 1.5707 1.5707" xyz="0 0 0"/>
      <geometry>
       <cylinder length="0.008" radius="0.05"/>
      </geometry>
    </collision>
    <visual name="link_left_wheel_visual">
      <origin rpy="0 1.5707 1.5707" xyz="0 0 0"/>
      <geometry>
        <cylinder length="0.008" radius="0.05"/>
      </geometry>
    </visual>
  </link>
  
  <joint name="joint_left_wheel" type="continuous">
    <origin rpy="0 0 0" xyz="0 0 0"/>
    <child link="link_left_wheel"/>
    <parent link="teker_cubuk_sol"/>
    <axis rpy="0 0 0" xyz="0 1 0"/>
    <limit effort="10000" velocity="1000"/>
    <joint_properties damping="1.0" friction="1.0"/>
</joint>

 <!-- cubuklar -->

  <link name="cubuk_1">
    <inertial>
      <mass value="0.125" />
      <origin xyz="0 0 0" rpy="0 0 0"/>
      <inertia ixx="0.0007030433333333334" ixy="0" ixz="0" iyy="0.0007030433333333334" iyz="0" izz="8e-06" />
    </inertial>
        <visual>
        <origin xyz="0 0 0" rpy="0 0 0" />
        <geometry>
        <cylinder radius="0.008" length="0.25"/>
        </geometry>
        <material name="gray" />
    </visual>

    <collision>
        <origin xyz="0 0 0" rpy="0 0 0"/>
        <geometry>
        <cylinder radius="0.008" length="0.25"/>
        </geometry>
    </collision>
    </link>

    <joint name="joint_cubuk_1" type="fixed">
    <origin xyz="0.02 0.06 0.125" rpy="0 0 0"/>
    <parent link="link_chassis"/>
    <child link="cubuk_1"/>
    </joint>


  <link name="cubuk_2">
    <inertial>
      <mass value="0.125" />
      <origin xyz="0 0 0" rpy="0 0 0"/>
       <inertia ixx="0.0007030433333333334" ixy="0" ixz="0" iyy="0.0007030433333333334" iyz="0" izz="8e-06" />
    </inertial>
        <visual>
        <origin xyz="0 0 0" rpy="0 0 0" />
        <geometry>
        <cylinder radius="0.008" length="0.25"/>
        </geometry>
        <material name="gray" />
    </visual>

    <collision>
        <origin xyz="0 0 0" rpy="0 0 0"/>
        <geometry>
        <cylinder radius="0.008" length="0.25"/>
        </geometry>
    </collision>
    </link>

    <joint name="joint_cubuk_2" type="fixed">
    <origin xyz="-0.02 0.06 0.125" rpy="0 0 0"/>
    <parent link="link_chassis"/>
    <child link="cubuk_2"/>
     </joint> 

  <link name="cubuk_3">
    <inertial>
      <mass value="0.125" />
      <origin xyz="0 0 0" rpy="0 0 0"/>
       <inertia ixx="0.0007030433333333334" ixy="0" ixz="0" iyy="0.0007030433333333334" iyz="0" izz="8e-06" />
    </inertial>
        <visual>
        <origin xyz="0 0 0" rpy="0 0 0" />
        <geometry>
        <cylinder radius="0.008" length="0.25"/>
        </geometry>
        <material name="gray" />
    </visual>

    <collision>
        <origin xyz="0 0 0" rpy="0 0 0"/>
        <geometry>
        <cylinder radius="0.008" length="0.25"/>
        </geometry>
    </collision>
    </link>

    <joint name="joint_cubuk_3" type="fixed">
    <origin xyz="0.02 -0.06 0.125" rpy="0 0 0"/>
    <parent link="link_chassis"/>
    <child link="cubuk_3"/>
   </joint> 

  <link name="cubuk_4">
    <inertial>
      <mass value="0.125" />
      <origin xyz="0 0 0" rpy="0 0 0"/>
       <inertia ixx="0.0007030433333333334" ixy="0" ixz="0" iyy="0.0007030433333333334" iyz="0" izz="8e-06" />
    </inertial>
        <visual>
        <origin xyz="0 0 0" rpy="0 0 0" />
        <geometry>
        <cylinder radius="0.008" length="0.25"/>
        </geometry>
        <material name="gray" />
    </visual>

    <collision>
        <origin xyz="0 0 0" rpy="0 0 0"/>
        <geometry>
        <cylinder radius="0.008" length="0.25"/>
        </geometry>
    </collision>
    </link>

    <joint name="joint_cubuk_4" type="fixed">
    <origin xyz="-0.02 -0.06 0.125" rpy="0 0 0"/>
    <parent link="link_chassis"/>
    <child link="cubuk_4"/>
  </joint> 

<link name="sensor_laser">
    <inertial>
      <mass value="1e-5" />
      <origin xyz="0 0 0" rpy="0 0 0"/>
      <inertia ixx="1e-6" ixy="0" ixz="0" iyy="1e-6" iyz="0" izz="1e-6" />
    </inertial>
        <visual>
        <origin xyz="0 0 0" rpy="0 0 0" />
        <geometry>
        <cylinder radius="0.025" length="0.01"/>
        </geometry>
        <material name="black" />
    </visual>

    <collision>
        <origin xyz="0 0 0" rpy="0 0 0"/>
        <geometry>
        <cylinder radius="0.025" length="0.02"/>
        </geometry>
    </collision>
    </link>

    <joint name="joint_sensor_laser" type="fixed">
    <origin xyz="0.0 0 0.125" rpy="0 0 0"/>
    <parent link="link_chassis"/>
    <child link="sensor_laser"/>
  </joint>
  


</robot>